
# Created by Ruins mod version 14.7 Ingame Parser
# authoring Player: skidznet

biomesToSpawnIn=ocean,deep ocean,kelp forest,ocean oil field,oceanic abyss,coral reef
weight=1
embed_into_distance=3
acceptable_target_blocks=water
unacceptable_target_blocks=flowing_water,flowing_lava,lava
dimensions=8,9,9
allowable_overhang=0
max_leveling=2
leveling_buffer=0
preserve_water=0
preserve_lava=0

rule1=0,100,minecraft:sand-0
rule2=0,100,minecraft:sandstone_stairs-1
rule3=0,100,chisel:tyrian-14
rule4=0,100,minecraft:water-1
rule5=0,100,minecraft:stained_hardened_clay-7
rule6=0,100,minecraft:water-0
rule7=0,100,minecraft:water-2
rule8=0,100,Forestry:fences-5

layer
1,1,1,1,1,1,1,1,1
1,1,0,0,0,0,0,1,1
1,0,0,0,0,0,0,0,1
1,0,0,0,0,0,0,0,1
1,0,0,2,0,0,0,0,1
1,0,0,0,0,0,0,0,1
1,0,0,3,0,0,0,0,1
1,1,0,0,0,0,0,1,1
1,1,1,0,0,0,1,1,1
endlayer

layer
1,1,1,1,1,1,1,1,1
1,1,0,0,0,0,0,1,1
1,0,0,0,0,0,0,0,1
1,0,0,0,0,0,0,0,1
1,0,0,0,0,0,0,0,1
1,0,0,0,0,0,0,0,1
1,0,0,0,0,0,0,0,1
1,1,0,0,0,0,0,1,1
1,1,1,1,1,1,1,1,1
endlayer

layer
6,6,6,5,5,5,4,4,4
4,4,5,5,5,5,5,7,7
0,5,5,5,5,5,5,5,7
5,5,5,5,5,5,5,5,5
5,5,5,5,5,5,5,5,5
5,5,5,5,5,5,5,5,5
0,5,5,5,5,5,5,5,6
0,0,5,5,5,5,5,4,6
0,0,0,5,5,5,0,4,6
endlayer

layer
0,0,0,0,0,0,0,0,0
0,0,0,5,5,5,0,0,0
0,0,5,5,5,5,5,0,0
0,5,5,5,5,5,5,5,0
0,5,5,5,5,5,5,5,0
0,5,5,5,5,5,5,5,0
0,0,5,5,5,5,5,0,0
0,0,0,5,5,5,0,0,0
0,0,0,0,0,0,0,0,0
endlayer

layer
0,0,0,0,0,0,0,0,0
0,0,0,0,0,0,0,0,0
0,0,0,5,5,5,0,0,0
0,0,5,5,5,5,5,0,0
0,0,5,5,5,5,5,0,0
0,0,5,5,5,5,5,0,0
0,0,0,5,5,5,0,0,0
0,0,0,0,0,0,0,0,0
0,0,0,0,0,0,0,0,0
endlayer

layer
0,0,0,0,0,0,0,0,0
0,0,0,0,0,0,0,0,0
0,0,0,0,0,0,0,0,0
0,0,0,5,5,5,0,0,0
0,0,0,5,5,5,0,0,0
0,0,0,5,5,5,0,0,0
0,0,0,0,0,0,0,0,0
0,0,0,0,0,0,0,0,0
0,0,0,0,0,0,0,0,0
endlayer

layer
0,0,0,0,0,0,0,0,0
0,0,0,0,0,0,0,0,0
0,0,0,0,0,0,0,0,0
0,0,0,0,0,0,0,0,0
0,0,0,0,8,0,0,0,0
0,0,0,0,0,0,0,0,0
0,0,0,0,0,0,0,0,0
0,0,0,0,0,0,0,0,0
0,0,0,0,0,0,0,0,0
endlayer

layer
0,0,0,0,0,0,0,0,0
0,0,0,0,0,0,0,0,0
0,0,0,0,0,0,0,0,0
0,0,0,0,8,0,0,0,0
0,0,0,0,8,0,0,0,0
0,0,0,0,8,0,0,0,0
0,0,0,0,0,0,0,0,0
0,0,0,0,0,0,0,0,0
0,0,0,0,0,0,0,0,0
endlayer

