
# Created by Ruins mod version 14.7 Ingame Parser
# authoring Player: skidznet

biomesToSpawnIn=ocean,deep ocean,kelp forest,ocean oil field,oceanic abyss,coral reef
weight=1
embed_into_distance=0
acceptable_target_blocks=
unacceptable_target_blocks=flowing_water,water,flowing_lava,lava
dimensions=9,6,6
allowable_overhang=0
max_leveling=2
leveling_buffer=0
preserve_water=0
preserve_lava=0

rule1=0,100,minecraft:water-0
rule2=0,100,Botany:ceramic-0
rule3=0,100,ExtraTrees:door-3
rule4=0,100,ExtraTrees:door-8
rule5=0,100,ExtraTrees:door-9
rule6=0,100,BiomesOPlenty:woodenSingleSlab1-7
rule7=0,100,chisel:glass-7
rule8=0,100,MobSpawner:Squid

layer
1,1,2,2,1,1
0,2,1,1,2,1
0,3,1,1,1,2
0,3,1,1,1,2
0,2,1,1,2,1
1,1,2,2,1,1
endlayer

layer
0,0,2,2,0,0
0,2,0,0,2,0
0,4,0,0,0,2
0,5,0,0,0,2
0,2,0,0,2,0
0,0,2,2,0,0
endlayer

layer
0,0,2,2,0,0
0,2,0,0,2,0
0,2,0,0,0,2
0,2,0,0,0,2
0,2,0,0,2,0
0,0,2,2,0,0
endlayer

layer
0,0,2,2,0,0
0,2,2,2,2,0
2,2,6,6,2,2
2,2,6,0,2,2
0,2,2,2,2,0
0,0,2,2,0,0
endlayer

layer
0,0,0,0,0,0
0,2,2,2,2,0
2,2,0,0,2,0
2,2,0,0,2,0
0,2,2,2,2,0
0,0,0,0,0,0
endlayer

layer
0,0,0,2,0,0
0,7,2,2,0,0
2,0,0,0,2,0
2,0,0,0,2,0
0,7,2,2,2,0
0,0,0,2,0,0
endlayer

layer
0,0,0,2,0,0
2,2,2,2,0,0
2,2,6,6,2,0
2,2,0,6,2,0
2,2,2,2,0,0
0,0,0,2,0,0
endlayer

layer
0,0,0,0,0,0
0,0,2,2,0,0
0,2,0,8,2,0
0,2,0,0,2,0
0,0,2,2,0,0
0,0,0,0,0,0
endlayer

layer
0,0,0,0,0,0
0,0,2,2,0,0
0,2,2,2,2,0
0,2,2,2,2,0
0,0,2,2,0,0
0,0,0,0,0,0
endlayer

