
# Created by Ruins mod version 14.7 Ingame Parser
# authoring Player: skidznet

weight=1
embed_into_distance=0
acceptable_target_blocks=
unacceptable_target_blocks=flowing_water,water,flowing_lava,lava
dimensions=7,6,7
allowable_overhang=0
max_leveling=2
leveling_buffer=0
preserve_water=0
preserve_lava=0

rule1=0,100,chisel:woolen_clay-14
rule2=0,100,Thaumcraft:blockWoodenDevice-6
rule3=0,100,BiblioWoodsBoP:BiblioWoodtable-5
rule4=0,100,chisel:carpet-8
rule5=0,100,imc:block_colored_flower_pot-0
rule6=0,100,Thaumcraft:blockJar-2
rule7=0,100,Thaumcraft:blockWoodenDevice-7
rule8=0,100,harvestcraft:pamcandleDeco1-3
rule9=0,100,minecraft:stone_slab-0

layer
0,0,0,0,0,0,0
0,0,1,1,1,1,0
0,0,1,1,1,1,0
0,0,1,1,1,1,0
0,0,1,1,1,1,0
0,0,0,0,0,0,0
endlayer

layer
0,2,2,2,2,2,0
0,0,0,0,0,0,2
0,0,0,4,4,3,2
0,0,0,4,4,3,2
0,0,0,0,0,0,2
0,2,2,2,2,2,0
endlayer

layer
0,0,2,2,2,2,0
0,0,0,0,0,0,2
0,0,0,0,0,5,2
0,0,0,0,0,6,2
0,0,0,0,0,0,2
0,0,2,2,2,2,0
endlayer

layer
0,0,0,7,7,7,0
0,0,0,0,0,0,7
0,0,0,0,0,0,7
0,0,0,0,0,0,7
0,0,0,0,0,0,7
0,0,0,7,7,7,0
endlayer

layer
0,0,0,0,7,7,0
0,0,0,0,0,8,7
0,0,0,0,0,0,7
0,0,0,0,0,0,7
0,0,0,0,0,8,7
0,0,0,0,7,7,0
endlayer

layer
0,0,0,0,0,7,0
0,0,0,0,0,0,7
0,0,0,0,0,0,7
0,0,0,0,0,0,7
0,0,0,0,0,0,7
0,0,0,0,0,7,0
endlayer

layer
0,0,0,0,0,9,0
0,0,0,0,9,9,9
0,0,0,0,9,9,9
0,0,0,0,9,9,9
0,0,0,0,9,9,9
0,0,0,0,0,9,0
endlayer

