
# Created by Ruins mod version 14.7 Ingame Parser
# authoring Player: skidznet

weight=3
embed_into_distance=0
acceptable_target_blocks=
unacceptable_target_blocks=flowing_water,water,flowing_lava,lava
dimensions=9,5,5
allowable_overhang=0
max_leveling=2
leveling_buffer=0
preserve_water=0
preserve_lava=0

rule1=0,100,witchery:icestockade-0
rule2=0,100,chisel:ice-14

layer
0,0,0,0,0
0,0,0,0,0
0,0,1,0,0
0,0,0,0,0
0,0,0,0,0
endlayer

layer
0,0,0,0,0
0,0,0,0,0
0,0,1,0,0
0,0,0,0,0
0,0,0,0,0
endlayer

layer
0,0,0,0,0
0,0,0,0,0
0,0,1,0,0
0,0,0,0,0
0,0,0,0,0
endlayer

layer
0,0,0,0,0
0,0,0,0,0
0,0,1,0,0
0,0,0,0,0
0,0,0,0,0
endlayer

layer
0,0,0,0,0
0,0,0,0,0
0,0,1,0,0
0,0,0,0,0
0,0,0,0,0
endlayer

layer
0,0,0,0,0
0,0,2,0,0
0,2,1,2,0
0,0,2,0,0
0,0,0,0,0
endlayer

layer
0,2,2,0,0
2,2,2,2,0
2,2,1,2,2
0,2,2,2,0
0,0,2,0,0
endlayer

layer
0,0,0,0,0
0,2,2,0,0
0,2,1,2,0
0,0,2,0,0
0,0,0,0,0
endlayer

layer
0,0,0,0,0
0,0,0,0,0
0,0,2,0,0
0,0,0,0,0
0,0,0,0,0
endlayer

