
# Created by Ruins mod version 15.3 Ingame Parser
# authoring Player: skidznet

weight=1
embed_into_distance=0
acceptable_target_blocks=
unacceptable_target_blocks=flowing_water,water,flowing_lava,lava
dimensions=5,18,18
allowable_overhang=0
max_leveling=2
leveling_buffer=0
preserve_water=0
preserve_lava=0

rule1=0,100,chisel:marble-0
rule2=0,100,chisel:marble_slab-0
rule3=0,100,minecraft:brown_mushroom_block-0
rule4=0,100,harvestcraft:spamcompressedsaltBlockalt-0
rule5=0,100,MineFactoryReloaded:mushroomsoup.still-1
rule6=0,100,MineFactoryReloaded:mushroomsoup.still-2
rule7=0,100,MineFactoryReloaded:mushroomsoup.still-3
rule8=0,100,minecraft:red_mushroom_block-0
rule9=0,100,MineFactoryReloaded:brick-13
rule10=0,100,BiomesOPlenty:logs3-7
rule11=0,100,BiomesOPlenty:colorizedLeaves1-12
rule12=0,100,BiomesOPlenty:logs3-11
rule13=0,100,Forestry:fluid.seedoil-1
rule14=0,100,BiomesOPlenty:bones-2
rule15=0,100,MineFactoryReloaded:mushroomsoup.still-0
rule16=0,100,MineFactoryReloaded:mushroomsoup.still-4
rule17=0,100,BiomesOPlenty:colorizedLeaves1-4
rule18=0,100,Forestry:fluid.seedoil-2
rule19=0,100,Forestry:fluid.seedoil-0

layer
0,0,0,0,0,0,0,0,0,0,0,0,0,0,0,0,0,0
0,0,0,0,0,0,1,1,1,1,1,1,0,0,0,0,0,0
0,0,0,0,1,1,1,1,1,1,1,1,1,1,0,0,0,0
0,0,0,1,1,1,1,1,1,1,1,1,1,1,1,0,0,0
0,0,1,1,1,1,1,1,1,1,1,1,1,1,1,1,0,0
0,0,1,1,1,1,1,1,1,1,1,1,1,1,1,1,0,0
0,1,1,1,1,1,1,1,1,1,1,1,1,1,1,1,1,0
0,1,1,1,1,1,1,1,1,1,1,1,1,1,1,1,1,0
0,1,1,1,1,1,1,1,1,1,1,1,1,1,1,1,1,0
0,1,1,1,1,1,1,1,1,1,1,1,1,1,1,1,1,0
0,1,1,1,1,1,1,1,1,1,1,1,1,1,1,1,1,0
0,1,1,1,1,1,1,1,1,1,1,1,1,1,1,1,1,0
0,0,1,1,1,1,1,1,1,1,1,1,1,1,1,1,0,0
0,0,1,1,1,1,1,1,1,1,1,1,1,1,1,1,0,0
0,0,0,1,1,1,1,1,1,1,1,1,1,1,1,0,0,0
0,0,0,0,1,1,1,1,1,1,1,1,1,1,0,0,0,0
0,0,0,0,0,0,1,1,1,1,1,1,0,0,0,0,0,0
0,0,0,0,0,0,0,0,0,0,0,0,0,0,0,0,0,0
endlayer

layer
0,0,0,0,0,0,1,1,1,1,1,1,0,0,0,0,0,0
0,0,0,0,1,1,2,2,2,2,2,2,1,1,0,0,0,0
0,0,0,1,2,2,4,7,6,5,3,4,3,2,1,0,0,0
0,0,1,2,0,0,0,3,3,5,8,8,3,6,2,1,0,0
0,1,2,0,0,0,0,3,3,8,5,4,5,5,6,2,1,0
0,1,2,0,0,0,0,3,3,5,5,3,3,8,8,2,1,0
1,2,0,0,9,0,8,6,5,5,3,3,4,8,8,4,2,1
1,2,0,9,9,9,0,8,3,5,8,0,8,0,0,8,2,1
1,2,0,9,9,9,0,8,8,8,4,0,0,0,0,0,2,1
1,2,9,9,9,9,9,8,8,0,0,0,10,0,10,0,2,1
1,2,9,9,9,9,9,0,0,0,0,11,10,11,10,11,2,1
1,2,0,9,9,9,0,0,0,0,0,11,10,11,11,11,2,1
0,1,2,9,9,9,0,0,0,0,11,11,10,11,11,2,1,0
0,1,2,0,9,0,0,0,0,12,12,12,11,11,11,2,1,0
0,0,1,2,0,0,0,0,0,0,0,11,13,11,2,1,0,0
0,0,0,1,2,2,0,0,0,0,11,0,2,2,1,0,0,0
0,0,0,0,1,1,2,2,2,2,2,2,1,1,0,0,0,0
0,0,0,0,0,0,1,1,1,1,1,1,0,0,0,0,0,0
endlayer

layer
0,0,0,0,0,0,0,0,0,0,0,0,0,0,0,0,0,0
0,0,0,0,0,0,0,0,0,0,0,0,0,0,0,0,0,0
0,0,0,0,0,0,0,0,0,0,3,0,3,0,0,0,0,0
0,0,0,14,0,14,0,3,3,6,8,8,3,0,0,0,0,0
0,0,0,0,14,0,0,3,15,5,5,15,5,0,0,0,0,0
0,0,0,0,14,0,0,3,3,6,6,3,3,8,8,0,0,0
0,0,0,9,14,9,0,0,0,7,7,8,0,8,0,0,0,0
0,0,0,9,14,9,0,3,3,16,8,0,0,0,0,0,0,0
0,0,9,9,14,9,9,8,0,0,0,0,0,0,0,0,0,0
0,0,9,9,14,9,9,8,8,0,0,0,0,0,0,0,0,0
0,0,9,9,14,9,9,0,0,0,0,0,17,0,11,0,0,0
0,0,9,9,9,9,9,0,0,0,0,11,18,11,11,0,0,0
0,0,0,9,9,9,0,0,0,0,17,18,13,19,13,17,0,0
0,0,0,9,9,9,0,0,0,0,0,11,11,11,17,0,0,0
0,0,0,0,0,0,0,0,0,0,0,0,13,19,17,0,0,0
0,0,0,0,0,0,0,0,0,0,0,0,0,0,0,0,0,0
0,0,0,0,0,0,0,0,0,0,0,0,0,0,0,0,0,0
0,0,0,0,0,0,0,0,0,0,0,0,0,0,0,0,0,0
endlayer

layer
0,0,0,0,0,0,0,0,0,0,0,0,0,0,0,0,0,0
0,0,0,0,0,0,0,0,0,0,0,0,0,0,0,0,0,0
0,0,0,0,0,0,0,0,0,0,0,0,0,0,0,0,0,0
0,0,0,0,0,0,0,0,0,0,0,0,0,0,0,0,0,0
0,0,0,0,0,0,0,0,0,0,0,0,0,0,0,0,0,0
0,0,0,0,0,0,0,0,0,0,0,0,0,0,0,0,0,0
0,0,0,0,9,0,0,0,0,0,0,0,0,0,0,0,0,0
0,0,0,9,9,9,0,0,0,0,0,0,0,0,0,0,0,0
0,0,9,9,9,9,9,0,0,0,0,0,0,0,0,0,0,0
0,0,9,9,9,9,9,0,0,0,0,0,0,0,0,0,0,0
0,0,9,9,9,9,9,0,0,0,0,0,0,0,0,0,0,0
0,0,9,9,9,9,9,0,0,0,0,0,0,0,0,0,0,0
0,0,0,9,9,9,0,0,0,0,0,0,0,0,0,0,0,0
0,0,0,0,9,0,0,0,0,0,0,0,0,0,0,0,0,0
0,0,0,0,0,0,0,0,0,0,0,0,0,0,0,0,0,0
0,0,0,0,0,0,0,0,0,0,0,0,0,0,0,0,0,0
0,0,0,0,0,0,0,0,0,0,0,0,0,0,0,0,0,0
0,0,0,0,0,0,0,0,0,0,0,0,0,0,0,0,0,0
endlayer

layer
0,0,0,0,0,0,0,0,0,0,0,0,0,0,0,0,0,0
0,0,0,0,0,0,0,0,0,0,0,0,0,0,0,0,0,0
0,0,0,0,0,0,0,0,0,0,0,0,0,0,0,0,0,0
0,0,0,0,0,0,0,0,0,0,0,0,0,0,0,0,0,0
0,0,0,0,0,0,0,0,0,0,0,0,0,0,0,0,0,0
0,0,0,0,0,0,0,0,0,0,0,0,0,0,0,0,0,0
0,0,0,0,0,0,0,0,0,0,0,0,0,0,0,0,0,0
0,0,0,0,9,0,0,0,0,0,0,0,0,0,0,0,0,0
0,0,0,9,9,9,0,0,0,0,0,0,0,0,0,0,0,0
0,0,9,9,9,9,9,0,0,0,0,0,0,0,0,0,0,0
0,0,9,9,9,9,9,0,0,0,0,0,0,0,0,0,0,0
0,0,0,9,9,9,0,0,0,0,0,0,0,0,0,0,0,0
0,0,0,0,9,0,0,0,0,0,0,0,0,0,0,0,0,0
0,0,0,0,0,0,0,0,0,0,0,0,0,0,0,0,0,0
0,0,0,0,0,0,0,0,0,0,0,0,0,0,0,0,0,0
0,0,0,0,0,0,0,0,0,0,0,0,0,0,0,0,0,0
0,0,0,0,0,0,0,0,0,0,0,0,0,0,0,0,0,0
0,0,0,0,0,0,0,0,0,0,0,0,0,0,0,0,0,0
endlayer

