
# Created by Ruins mod version 15.4 Ingame Parser
# authoring Player: skidznet

weight=1
embed_into_distance=0
acceptable_target_blocks=
unacceptable_target_blocks=flowing_water,water,flowing_lava,lava
dimensions=6,9,8
allowable_overhang=0
max_leveling=2
leveling_buffer=0
preserve_water=0
preserve_lava=0

rule1=0,100,ExtraUtilities:decorativeBlock2-6
rule2=0,100,chisel:glass-1
rule3=0,100,ExtraUtilities:decorativeBlock2-2
rule4=0,100,minecraft:glass-0
rule5=0,100,chisel:ice_stairs.5-9
rule6=0,100,chisel:glass_pane-1
rule7=0,100,chisel:ice_stairs.5-8
rule8=0,100,chisel:torch10-5
rule9=0,100,IInventory;BiblioCraft:BiblioStuffs;chisel:smashingrock#64#0#4-0
rule10=0,100,minecraft:glass_pane-0
rule11=0,100,chisel:carpet-0
rule12=0,100,ExtraUtilities:decorativeBlock2-9

layer
0,0,0,0,0,0,0,0
0,1,1,1,1,1,1,0
0,1,1,1,1,1,1,0
0,1,1,1,1,1,1,0
0,1,1,1,1,1,1,0
0,1,1,1,1,1,1,0
0,1,1,1,1,1,1,0
0,0,2,2,2,0,0,0
0,0,2,2,2,0,0,0
endlayer

layer
0,0,0,0,0,0,0,0
0,3,3,3,3,3,3,0
0,3,5,0,4,4,3,0
0,3,6,0,0,0,3,0
0,3,6,0,0,0,3,0
0,3,7,0,0,0,3,0
0,3,3,0,3,3,3,0
0,0,0,0,0,0,0,0
0,0,0,0,0,0,0,0
endlayer

layer
0,0,0,0,0,0,0,0
0,3,3,3,3,3,3,0
0,3,0,0,9,8,3,0
0,10,11,0,0,0,10,0
0,10,11,0,0,0,10,0
0,3,0,0,0,0,3,0
0,3,3,0,3,10,3,0
0,0,0,0,0,0,0,0
0,0,0,0,0,0,0,0
endlayer

layer
12,12,12,12,12,12,12,12
12,3,3,3,3,3,3,12
12,3,0,0,0,0,3,12
12,3,0,0,0,0,3,12
12,3,0,0,0,0,3,12
12,3,0,0,0,0,3,12
12,3,3,3,3,3,3,12
12,12,12,12,12,12,12,12
0,0,0,0,0,0,0,0
endlayer

layer
0,0,0,0,0,0,0,0
0,12,12,12,12,12,12,0
0,12,2,2,2,2,12,0
0,12,2,2,2,2,12,0
0,12,2,2,2,2,12,0
0,12,2,2,2,2,12,0
0,12,12,12,12,12,12,0
0,0,0,0,0,0,0,0
0,0,0,0,0,0,0,0
endlayer

layer
0,0,0,0,0,0,0,0
0,0,0,0,0,0,0,0
0,0,12,12,12,12,0,0
0,0,12,12,12,12,0,0
0,0,12,12,12,12,0,0
0,0,12,12,12,12,0,0
0,0,0,0,0,0,0,0
0,0,0,0,0,0,0,0
0,0,0,0,0,0,0,0
endlayer

