
# Created by Ruins mod version 15.4 Ingame Parser
# authoring Player: skidznet

weight=1
embed_into_distance=0
acceptable_target_blocks=
unacceptable_target_blocks=flowing_water,water,flowing_lava,lava
dimensions=10,8,8
allowable_overhang=0
max_leveling=2
leveling_buffer=0
preserve_water=0
preserve_lava=0

rule1=0,100,minecraft:stained_glass-5
rule2=0,100,Forestry:fluid.juice-0
rule3=0,100,ExtraUtilities:color_lightgem-4
rule4=0,100,Forestry:fluid.juice-1
rule5=0,100,BiomesOPlenty:sacredoakStairs-6
rule6=0,100,chisel:leaves-7
rule7=0,100,BiomesOPlenty:sacredoakStairs-3

layer
0,0,0,0,0,0,0,0
0,0,0,0,0,0,0,0
0,0,0,1,1,0,0,0
0,0,1,1,1,1,0,0
0,0,1,1,1,1,0,0
0,0,0,1,1,0,0,0
0,0,0,0,0,0,0,0
0,0,0,0,0,0,0,0
endlayer

layer
0,0,0,0,0,0,0,0
0,0,0,1,1,0,0,0
0,0,1,2,2,1,0,0
0,1,2,3,3,2,1,0
0,1,2,3,3,2,1,0
0,0,1,2,2,1,0,0
0,0,0,1,1,0,0,0
0,0,0,0,0,0,0,0
endlayer

layer
0,0,0,0,0,0,0,0
0,0,0,1,1,0,0,0
0,0,1,1,1,1,0,0
0,1,1,2,2,1,1,0
0,1,1,2,2,1,1,0
0,0,1,1,1,1,0,0
0,0,0,1,1,0,0,0
0,0,0,0,0,0,0,0
endlayer

layer
0,0,0,0,0,0,0,0
0,0,0,0,0,0,0,0
0,0,0,1,1,0,0,0
0,0,1,2,4,1,0,0
0,0,1,4,2,1,0,0
0,0,0,1,1,0,0,0
0,0,0,0,0,0,0,0
0,0,0,0,0,0,0,0
endlayer

layer
0,0,0,0,0,0,0,0
0,0,0,0,0,0,0,0
0,0,0,1,1,0,0,0
0,0,1,4,2,1,0,0
0,0,1,2,4,1,0,0
0,0,0,1,1,0,0,0
0,0,0,0,0,0,0,0
0,0,0,0,0,0,0,0
endlayer

layer
0,0,0,0,0,0,0,0
0,0,0,0,0,0,0,0
0,0,0,0,0,0,0,0
0,0,0,1,1,0,0,0
0,0,0,1,1,0,0,0
0,0,0,0,0,0,0,0
0,0,0,0,0,0,0,0
0,0,0,0,0,0,0,0
endlayer

layer
0,0,0,0,0,0,0,0
0,0,0,0,0,0,0,0
0,0,0,0,0,0,0,0
0,0,0,0,0,0,0,0
0,0,0,6,6,5,0,0
0,0,0,6,0,0,0,0
0,0,0,0,0,0,0,0
0,0,0,0,0,0,0,0
endlayer

layer
0,0,0,0,0,0,0,0
0,0,0,0,0,0,0,0
0,0,0,0,0,0,0,0
0,0,0,0,0,0,0,0
0,0,0,0,0,7,5,0
0,0,6,6,0,0,0,0
0,0,0,0,0,0,0,0
0,0,0,0,0,0,0,0
endlayer

layer
0,0,0,0,0,0,0,0
0,0,0,0,0,0,0,0
0,0,0,0,0,0,0,0
0,0,0,0,0,0,0,0
0,0,0,0,0,0,0,0
0,6,6,6,0,0,0,0
0,0,0,0,0,0,0,0
0,0,0,0,0,0,0,0
endlayer

layer
0,0,0,0,0,0,0,0
0,0,0,0,0,0,0,0
0,0,0,0,0,0,0,0
0,0,0,0,0,0,0,0
0,0,0,0,0,0,0,0
0,0,6,0,0,0,0,0
0,0,0,0,0,0,0,0
0,0,0,0,0,0,0,0
endlayer

