
# Created by Ruins mod version 14.7 Ingame Parser
# authoring Player: skidznet

weight=1
embed_into_distance=0
acceptable_target_blocks=
unacceptable_target_blocks=flowing_water,water,flowing_lava,lava
dimensions=4,11,6
allowable_overhang=0
max_leveling=2
leveling_buffer=0
preserve_water=0
preserve_lava=0

rule1=0,100,BiomesOPlenty:bones-2
rule2=0,100,MineFactoryReloaded:sludge.still-2
rule3=0,100,MineFactoryReloaded:sludge.still-1
rule4=0,100,Thaumcraft:blockTaint-2
rule5=0,100,BiomesOPlenty:bones-6
rule6=0,100,MineFactoryReloaded:sludge.still-0
rule7=0,100,Metallurgy:utility.block-4
rule8=0,100,TConstruct:liquid.blood-0
rule9=0,100,BiomesOPlenty:bones-1

layer
0,0,0,0,0,0
0,0,1,0,0,0
0,4,1,4,3,2
4,1,1,1,3,3
4,4,1,4,0,0
4,1,1,1,4,0
0,4,1,4,0,0
0,4,0,0,0,0
0,0,1,0,0,0
0,0,0,0,0,0
0,1,0,0,0,0
endlayer

layer
0,0,0,0,0,0
0,0,5,0,0,0
0,0,1,0,0,0
0,7,1,6,3,0
4,1,8,1,0,0
0,1,1,1,0,0
0,4,9,0,0,0
0,0,0,0,0,0
0,0,9,0,0,0
0,0,0,0,0,0
0,9,0,0,0,0
endlayer

layer
0,0,0,0,0,0
0,0,0,0,0,0
0,4,4,0,0,0
4,1,1,1,0,0
0,4,1,0,0,0
0,4,4,4,0,0
0,0,0,0,0,0
0,0,0,0,0,0
0,0,0,0,0,0
0,0,0,0,0,0
0,0,0,0,0,0
endlayer

layer
0,0,0,0,0,0
0,0,0,0,0,0
0,0,0,0,0,0
0,4,4,0,0,0
0,0,4,0,0,0
0,0,0,0,0,0
0,0,0,0,0,0
0,0,0,0,0,0
0,0,0,0,0,0
0,0,0,0,0,0
0,0,0,0,0,0
endlayer

