
# Created by Ruins mod version 14.7 Ingame Parser
# authoring Player: skidznet

weight=3
embed_into_distance=0
acceptable_target_blocks=
unacceptable_target_blocks=flowing_water,water,flowing_lava,lava
dimensions=10,8,6
allowable_overhang=0
max_leveling=2
leveling_buffer=0
preserve_water=0
preserve_lava=0

rule1=0,100,witchery:stockade-7
rule2=0,100,minecraft:leaves2-4
rule3=0,100,minecraft:leaves2-12

layer
0,0,0,0,0,0
0,0,0,0,0,0
0,0,0,0,0,0
0,0,0,1,0,0
0,0,0,0,0,0
0,0,0,0,0,0
0,0,0,0,0,0
0,0,0,0,0,0
endlayer

layer
0,0,0,0,0,0
0,0,0,0,0,0
0,0,0,0,0,0
0,0,0,1,0,0
0,0,0,0,0,0
0,0,0,0,0,0
0,0,0,0,0,0
0,0,0,0,0,0
endlayer

layer
0,0,0,0,0,0
0,0,0,0,0,0
0,0,0,0,0,0
0,0,0,1,0,0
0,0,0,0,0,0
0,0,0,0,0,0
0,0,0,0,0,0
0,0,0,0,0,0
endlayer

layer
0,0,0,0,0,0
0,0,0,0,0,0
0,0,0,0,0,0
0,0,0,1,0,0
0,0,0,0,0,0
0,0,0,0,0,0
0,0,0,0,0,0
0,0,0,0,0,0
endlayer

layer
0,0,0,0,0,0
0,0,0,0,0,0
0,0,0,0,0,0
0,0,0,1,0,0
0,0,0,0,0,0
0,0,0,0,0,0
0,0,0,0,0,0
0,0,0,0,0,0
endlayer

layer
0,0,0,0,0,0
0,0,0,0,0,0
0,0,0,0,0,0
0,0,0,1,0,0
0,0,0,0,0,0
0,0,0,0,0,0
0,0,0,0,0,0
0,0,0,0,0,0
endlayer

layer
0,0,2,2,0,0
0,0,2,2,3,0
0,0,2,2,0,0
0,0,0,1,0,0
0,0,2,2,2,0
0,2,2,2,2,0
0,2,2,2,2,0
0,0,2,2,0,0
endlayer

layer
0,0,0,0,0,0
0,2,2,2,3,0
0,2,3,3,3,3
2,2,2,1,3,2
2,2,2,2,2,2
0,2,2,2,2,2
0,0,0,0,0,0
0,0,0,0,0,0
endlayer

layer
0,0,0,0,0,0
0,0,0,0,0,0
0,0,2,3,3,0
0,0,3,1,3,0
0,0,2,2,2,0
0,0,0,0,0,0
0,0,0,0,0,0
0,0,0,0,0,0
endlayer

layer
0,0,0,0,0,0
0,0,0,0,0,0
0,0,0,0,0,0
0,0,0,3,0,0
0,0,0,0,0,0
0,0,0,0,0,0
0,0,0,0,0,0
0,0,0,0,0,0
endlayer

