
# Created by Ruins mod version 14.7 Ingame Parser
# authoring Player: skidznet

weight=1
embed_into_distance=0
acceptable_target_blocks=
unacceptable_target_blocks=flowing_water,water,flowing_lava,lava
dimensions=3,10,13
allowable_overhang=0
max_leveling=2
leveling_buffer=0
preserve_water=0
preserve_lava=0

rule1=0,100,minecraft:leaves-12
rule2=0,100,BiomesOPlenty:moss-8
rule3=0,100,BiomesOPlenty:moss-1
rule4=0,100,minecraft:log-0
rule5=0,100,minecraft:log-8
rule6=0,100,minecraft:log-4
rule7=0,100,BiomesOPlenty:moss-9
rule8=0,100,minecraft:leaves-4
rule9=0,100,BiomesOPlenty:moss-2
rule10=0,100,harvestcraft:mushroomgarden-0

layer
0,0,0,1,0,0,0,0,0,0,0,0,0
0,0,1,1,1,2,0,0,0,0,0,0,0
0,0,1,5,5,4,3,0,1,0,0,0,0
0,1,1,1,8,4,7,0,1,6,0,0,0
0,0,5,5,5,5,5,5,5,5,5,0,0
0,0,0,5,5,5,5,5,5,5,5,5,5
0,1,1,1,6,1,0,0,9,0,0,0,0
0,1,1,1,1,1,0,1,1,0,0,0,0
0,0,0,8,1,1,0,1,1,1,0,0,0
0,0,0,0,0,0,0,0,1,0,0,0,0
endlayer

layer
0,0,0,0,0,0,0,0,0,0,0,0,0
0,0,0,1,0,2,0,0,0,0,0,0,0
0,0,1,1,1,6,3,0,0,0,0,0,0
0,0,0,1,2,1,0,0,0,1,0,0,0
0,0,1,0,5,5,5,5,0,5,0,0,0
0,5,5,5,5,5,5,5,5,5,5,0,0
0,1,1,1,1,1,0,6,0,0,0,0,0
0,0,0,8,8,0,0,6,1,0,0,0,0
0,0,0,0,0,0,0,1,1,0,0,0,0
0,0,0,0,0,0,0,0,0,0,0,0,0
endlayer

layer
0,0,0,0,0,0,0,0,0,0,0,0,0
0,0,0,0,0,0,0,0,0,0,0,0,0
0,0,0,0,0,0,0,0,0,0,0,0,0
0,0,0,0,0,0,0,0,0,0,0,0,0
0,0,0,0,0,0,0,0,0,0,0,0,0
0,0,0,8,0,10,0,0,0,0,0,0,0
0,0,0,8,8,0,0,0,0,0,0,0,0
0,0,0,0,0,0,0,1,0,0,0,0,0
0,0,0,0,0,0,0,0,0,0,0,0,0
0,0,0,0,0,0,0,0,0,0,0,0,0
endlayer

